Workbook

Sheet Index
D3: 1 | E3: Login Credentials (URL, User, Password, PIN)
D4: 2 | E4: SBI Securities (Tracking, Sell, Buy)
D5: 3 | E5: Mutual Funds
F6: India
F7: Japan
D8: 4 | E8: Ricardo`s Demise
D9: 5 | E9: Kaori`s Demise
D10: 6 | E10: Tanaka Kikinzoku
D11: 7 | E11: Crypto Currency
F12: Current Assets
F13: Wallets
F14: Buy and Sell
F15: Educational Videos
D16: 8 | E16: NRO, NRE
D17: 9 | E17: Tenant Information
F18: India
F19: Japan
D20: 10 | E20: Banks, Cash
D21: 11 | E21: Physical Gold India
D22: 12 | E22: Life Insurance Policies
F23: India
F24: Japan
D25: 13 | E25: Fixed Deposits
D26: 14 | E26: Passive Income
D27: 15 | E27: Real Estate
F28: India
F29: Japan
D30: 16 | E30: Stamps
D31: 17 | E31: Loans
F32: Taken
F33: Given
D34: 18 | E34: NISA
F35: Old Nisa
F36: New Nisa
F37: Tsumitate Nisa
D38: 19 | E38: Japanese Pension (年金）
D39: 20 | E39: Souzokuzei (相続税)
D40: 21 | E40: Global Assets
F41: Summary
F42: Details

Sheet Global Assets (2)
A1: As on 22-4-2026
B2: Real estate | I2: 1 USD | J2: 159.5 | K2: JPY
C3: India | I3: 1 USD | J3: 93.8 | K3: INR
D4: Current Sale Price | E4: Flat | F4: INR | G4: JPY | H4: USD | I4: 1 INR | J4: 1.7 | K4: JPY
E5: Poonam Residency | F5: 10500000 | G5: =F5*J4 -> 17850000 | H5: =F5/J3 -> 111940.3
E6: Sunway Megapolis | F6: 8500000 | G6: =F6*J4 -> 14450000 | H6: =F6/J3 -> 90618.337
E7: Osia Maple Leaf | F7: 7500000 | G7: =F7*J4 -> 12750000 | H7: =F7/J3 -> 79957.356
E8: Venusta Classic | F8: 5500000 | G8: =F8*J4 -> 9350000 | H8: =F8/J3 -> 58635.394
E9: Altamonte | F9: 4500000 | G9: =F9*J4 -> 7650000 | H9: =F9/J3 -> 47974.414
E10: Osia Arcade | F10: 2000000 | G10: =F10*J4 -> 3400000 | H10: =F10/J3 -> 21321.962
E11: Total | F11: =SUM(F5:F10) -> 38500000 | G11: =SUM(G5:G10) -> 65450000 | H11: =SUM(H5:H10) -> 410447.76
C12: Japan
D13: Capital repayment | E13: Flat | F13: JPY | G13: INR | H13: USD | I13: Purchase Amt JPY
E14: Ober Grandious | F14: 12781330 | G14: =F14/J4 -> 7518429.4 | H14: =F14/J2 -> 80133.73 | I14: 38000000
E15: Phoenix Waseda | F15: 3400750 | G15: =F15/J4 -> 2000441.2 | H15: =F15/J2 -> 21321.317 | I15: 15000000
E16: Urban Hills Waseda | F16: 2952420 | G16: =F16/J4 -> 1736717.6 | H16: =F16/J2 -> 18510.47 | I16: 13500000
E17: Lions Plaza Hakusan | F17: 2140772 | G17: =F17/J4 -> 1259277.6 | H17: =F17/J2 -> 13421.768 | I17: 11000000
E18: Castle mansion | F18: 2294411 | G18: =F18/J4 -> 1349653.5 | H18: =F18/J2 -> 14385.022 | I18: 13500000
E19: Total | F19: =SUM(F13:F18) -> 23569683 | G19: =SUM(G13:G18) -> 13864519 | H19: =SUM(H13:H18) -> 147772.31 | I19: =SUM(I13:I18) -> 91000000 | J19: =I19-F19 -> 67430317
D21: Current Sale Price | E21: Flat | F21: Purchase Price JPY | G21: Sale Price JPY | H21: Unrealized Profit JPY | I21: INR | J21: USD
E22: Ober Grandious | F22: 38000000 | G22: =F22*0.3 + F22 -> 49400000 | H22: =G22-F22 -> 11400000 | I22: =H22*J4 -> 19380000 | J22: =H22/J3 -> 121535.18
E23: Phoenix Waseda | F23: 15000000 | G23: =F23*0.3 + F23 -> 19500000 | H23: =G23-F23 -> 4500000 | I23: =H23*J4 -> 7650000 | J23: =H23/J3 -> 47974.414
E24: Urban Hills Waseda | F24: 13500000 | G24: =F24*0.3 + F24 -> 17550000 | H24: =G24-F24 -> 4050000 | I24: =H24*J4 -> 6885000 | J24: =H24/J3 -> 43176.972
E25: Lions Plaza Hakusan | F25: 11000000 | G25: =F25*0.3 + F25 -> 14300000 | H25: =G25-F25 -> 3300000 | I25: =H25*J4 -> 5610000 | J25: =H25/J3 -> 35181.237
E26: Castle mansion | F26: 13500000 | G26: =F26*0.3 + F26 -> 17550000 | H26: =G26-F26 -> 4050000 | I26: =H26*J4 -> 6885000 | J26: =H26/J3 -> 43176.972
E27: Total | F27: =SUM(F22:F26) -> 91000000 | G27: =SUM(G22:G26) -> 118300000 | H27: =SUM(H22:H26) -> 27300000 | I27: =SUM(I22:I26) -> 46410000 | J27: =SUM(J22:J26) -> 291044.78
D30: Capital repayment + Unrealized Profit
E31: Flat | F31: Profit JPY | G31: INR | H31: USD
E32: Ober Grandious | F32: =H22+F14 -> 24181330 | G32: =F32/J4 -> 14224312 | H32: =G32/J3 -> 151645.11
E33: Phoenix Waseda | F33: =H23+F15 -> 7900750 | G33: =F33/J4 -> 4647500 | H33: =G33/J3 -> 49546.908
E34: Urban Hills Waseda | F34: =H24+F16 -> 7002420 | G34: =F34/J4 -> 4119070.6 | H34: =G34/J3 -> 43913.332
E35: Lions Plaza Hakusan | F35: =H25+F17 -> 5440772 | G35: =F35/J4 -> 3200454.1 | H35: =G35/J3 -> 34119.98
E36: Castle mansion | F36: =H26+F18 -> 6344411 | G36: =F36/J4 -> 3732006.5 | H36: =G36/J3 -> 39786.849
E37: Total | F37: =SUM(F32:F36) -> 50869683 | G37: =SUM(G32:G36) -> 29923343 | H37: =SUM(H32:H36) -> 319012.18
B41: Cash
C42: India
D43: Fixed Deposits
E44: Bank | F44: USD | G44: INR | H44: JPY
E45: State Bank of India | F45: 292018 | G45: =F45*J3 -> 27391288 | H45: =F45*J2 -> 46576871
E46: State Bank of India | F46: 5070 | G46: =F46*J3 -> 475566 | H46: =F46*J2 -> 808665
...

Sheet Global Assets
A2: Region | B2: Asset Category | C2: Asset Owner | D2: Asset | E2: INR | F2: USD | G2: JPY
A3: India | B3: Real estate | C3: Ricardo | D3: Poonam Residency | E3: 10500000 | F3: =E3/Formula!B3 -> 111940.3 | G3: =E3*Formula!B4 -> 17850000
A4: - | B4: - | C4: - | D4: Sunway Megapolis | E4: 8500000 | F4: =E4/Formula!B3 -> 90618.337 | G4: =E4*Formula!B4 -> 14450000
A5: - | B5: - | C5: - | D5: Osia Maple Leaf | E5: 7500000 | F5: =E5/Formula!B3 -> 79957.356 | G5: =E5*Formula!B4 -> 12750000
A6: - | B6: - | C6: - | D6: Venusta Classic | E6: 5500000 | F6: =E6/Formula!B3 -> 58635.394 | G6: =E6*Formula!B4 -> 9350000
A7: - | B7: - | C7: - | D7: Altamonte | E7: 4500000 | F7: =E7/Formula!B3 -> 47974.414 | G7: =E7*Formula!B4 -> 7650000
A8: - | B8: - | C8: - | D8: Osia Arcade | E8: 2000000 | F8: =E8/Formula!B3 -> 21321.962 | G8: =E8*Formula!B4 -> 3400000
A9: India | B9: Fixed Deposits | C9: Ricardo | D9: State Bank of India | E9: =F9*Formula!B3 -> 27391288 | F9: 292018 | G9: =F9*Formula!B2 -> 46576871
A10: - | B10: - | C10: - | D10: State Bank of India | E10: =F10*Formula!B3 -> 475566 | F10: 5070 | G10: =F10*Formula!B2 -> 808665
A11: - | B11: - | C11: - | D11: Bank of India | E11: =F11*Formula!B3 -> 8534955.8 | F11: 90991 | G11: =F11*Formula!B2 -> 14513064
A12: - | B12: - | C12: - | D12: Bank of India | E12: =F12*Formula!B3 -> 220523.8 | F12: 2351 | G12: =F12*Formula!B2 -> 374984.5
A13: - | B13: - | C13: - | D13: HDFC Bank | E13: =F13*Formula!B3 -> 1594600 | F13: 17000 | G13: =F13*Formula!B2 -> 2711500
A14: - | B14: - | C14: - | D14: Bank of Baroda | E14: =F14*Formula!B3 -> 440015.8 | F14: 4691 | G14: =F14*Formula!B2 -> 748214.5
A15: - | B15: - | C15: - | D15: Yes Bank | E15: =F15*Formula!B3 -> 83013 | F15: 885 | G15: =F15*Formula!B2 -> 141157.5
A16: India | B16: Cash in Bank | C16: Ricardo | D16: State Bank of India NRE | E16: 10280 | F16: =E16/Formula!B3 -> 109.59488 | G16: =F16*Formula!B2 -> 17480.384
A17: - | B17: - | C17: - | D17: State Bank of India NRO | E17: 10000 | F17: =E17/Formula!B3 -> 106.60981 | G17: =F17*Formula!B2 -> 17004.264
A18: - | B18: - | C18: - | D18: Bank of India NRE | E18: 385004 | F18: =E18/Formula!B3 -> 4104.5203 | G18: =F18*Formula!B2 -> 654670.98
A19: - | B19: - | C19: - | D19: Bank of India NRO | E19: 2141703 | F19: =E19/Formula!B3 -> 22832.655 | G19: =F19*Formula!B2 -> 3641808.4
A20: - | B20: - | C20: - | D20: ICICI Bank NRO | E20: =3637285+963533 -> 4600818 | F20: =E20/Formula!B3 -> 49049.232 | G20: =F20*Formula!B2 -> 7823352.6
A21: - | B21: - | C21: - | D21: Bank of Baroda NRO | E21: 30000 | F21: =E21/Formula!B3 -> 319.82942 | G21: =F21*Formula!B2 -> 51012.793
A22: - | B22: - | C22: - | D22: HDFC Bank NRE | E22: 10000 | F22: =E22/Formula!B3 -> 106.60981 | G22: =F22*Formula!B2 -> 17004.264
A23: - | B23: - | C23: - | D23: HDFC Bank NRO | E23: 10000 | F23: =E23/Formula!B3 -> 106.60981 | G23: =F23*Formula!B2 -> 17004.264
A24: - | B24: - | C24: - | D24: Yes Bank NRE | E24: 83000 | F24: =E24/Formula!B3 -> 884.86141 | G24: =F24*Formula!B2 -> 141135.39
A25: - | B25: - | C25: - | D25: Yes Bank NRO | E25: 10000 | F25: =E25/Formula!B3 -> 106.60981 | G25: =F25*Formula!B2 -> 17004.264
A26: - | B26: - | C26: - | D26: Shriram FD | E26: 500000 | F26: =E26/Formula!B3 -> 5330.4904 | G26: =F26*Formula!B2 -> 850213.22
A27: India | B27: Cash in Bank | C27: Veronica | D27: State Bank of India | E27: 0 | F27: =E27/Formula!B3 -> 0 | G27: =F27*Formula!B2 -> 0
A28: - | B28: - | C28: - | D28: ICICI Bank | E28: 755193 | F28: =E28/Formula!B3 -> 8051.0981 | G28: =F28*Formula!B2 -> 1284150.1
A29: - | B29: - | C29: - | D29: Bank of Baroda | E29: 152000 | F29: =E29/Formula!B3 -> 1620.4691 | G29: =F29*Formula!B2 -> 258464.82
A30: - | B30: - | C30: - | D30: Punjab National | E30: 0 | F30: =E30/Formula!B3 -> 0 | G30: =F30*Formula!B2 -> 0
A31: - | B31: - | C31: - | D31: Post Office | E31: 0 | F31: =E31/Formula!B3 -> 0 | G31: =F31*Formula!B2 -> 0
A32: India | B32: Cash in Bank | C32: Bong | D32: State Bank of India | E32: 160000 | F32: =E32/Formula!B3 -> 1705.7569 | G32: =F32*Formula!B2 -> 272068.23
A33: - | B33: - | C33: Paul | D33: Yes Bank | E33: 0 | F33: =E33/Formula!B3 -> 0 | G33: =F33*Formula!B2 -> 0
A34: India | B34: Cash Loans given to Family | C34: Ricardo | D34: Sabrina | E34: 1057500 | F34: =E34/Formula!B3 -> 11273.987 | G34: =E34*Formula!B4 -> 1797750
A35: - | B35: - | C35: - | D35: Julian | E35: 332000 | F35: =E35/Formula!B3 -> 3539.4456 | G35: =E35*Formula!B4 -> 564400
A36: - | B36: - | C36: - | D36: Subuhi | E36: 898000 | F36: =E36/Formula!B3 -> 9573.5608 | G36: =E36*Formula!B4 -> 1526600
A37: - | B37: - | C37: - | D37: Jagdish | E37: 1200000 | F37: =E37/Formula!B3 -> 12793.177 | G37: =E37*Formula!B4 -> 2040000
A38: India | B38: Stocks | C38: Ricardo | D38: Finolex Industries | E38: 79045 | F38: =E38/Formula!B3 -> 842.69723 | G38: =E38*Formula!B4 -> 134376.5
A39: - | B39: - | C39: - | D39: Hindustan Foods | E39: 243475 | F39: =E39/Formula!B3 -> 2595.6823 | G39: =E39*Formula!B4 -> 413907.5
A40: - | B40: - | C40: - | D40: NCL Industries | E40: 68360 | F40: =E40/Formula!B3 -> 728.78465 | G40: =E40*Formula!B4 -> 116212
A41: India | B41: Vernonica Portfolio | C41: Veronica | D41: Stocks | E41: 85433 | F41: =E41/Formula!B3 -> 910.79957 | G41: =E41*Formula!B4 -> 145236.1
...

Sheet Formula
A2: 1 USD | B2: 159.5 | C2: JPY
A3: 1 USD | B3: 93.8 | C3: INR
A4: 1 INR | B4: 1.7 | C4: JPY

Sheet Global Assets -old
A1: As on 22-4-2026
B2: Real estate | I2: 1 USD | J2: 159.5 | K2: JPY
B3: India | I3: 1 USD | J3: 93.8 | K3: INR
B4: Current Sale Price | C4: Flat | D4: INR | E4: JPY | F4: USD | I4: 1 INR | J4: 1.7 | K4: JPY
C5: Poonam Residency | D5: 10500000 | E5: =D5*J4 -> 17850000 | F5: =D5/J3 -> 111940.3
C6: Sunway Megapolis | D6: 8500000 | E6: =D6*J4 -> 14450000 | F6: =D6/J3 -> 90618.337
C7: Osia Maple Leaf | D7: 7500000 | E7: =D7*J4 -> 12750000 | F7: =D7/J3 -> 79957.356
C8: Venusta Classic | D8: 5500000 | E8: =D8*J4 -> 9350000 | F8: =D8/J3 -> 58635.394
C9: Altamonte | D9: 4500000 | E9: =D9*J4 -> 7650000 | F9: =D9/J3 -> 47974.414
C10: Osia Arcade | D10: 2000000 | E10: =D10*J4 -> 3400000 | F10: =D10/J3 -> 21321.962
C11: Total | D11: =SUM(D5:D10) -> 38500000 | E11: =SUM(E5:E10) -> 65450000 | F11: =SUM(F5:F10) -> 410447.76
B13: Japan
B14: Capital repayment | C14: Flat | D14: JPY | E14: INR | F14: USD | G14: Purchase Amt JPY
C15: Ober Grandious | D15: 12781330 | E15: =D15/J4 -> 7518429.4 | F15: =D15/J2 -> 80133.73 | G15: 38000000
C16: Phoenix Waseda | D16: 3400750 | E16: =D16/J4 -> 2000441.2 | F16: =D16/J2 -> 21321.317 | G16: 15000000
C17: Urban Hills Waseda | D17: 2952420 | E17: =D17/J4 -> 1736717.6 | F17: =D17/J2 -> 18510.47 | G17: 13500000
C18: Lions Plaza Hakusan | D18: 2140772 | E18: =D18/J4 -> 1259277.6 | F18: =D18/J2 -> 13421.768 | G18: 11000000
C19: Castle mansion | D19: 2294411 | E19: =D19/J4 -> 1349653.5 | F19: =D19/J2 -> 14385.022 | G19: 13500000
C20: Total | D20: =SUM(D14:D19) -> 23569683 | E20: =SUM(E14:E19) -> 13864519 | F20: =SUM(F14:F19) -> 147772.31 | G20: =SUM(G14:G19) -> 91000000 | H20: =G20-D20 -> 67430317
B22: Current Sale Price | C22: Flat | D22: Purchase Price JPY | E22: Sale Price JPY | F22: Unrealized Profit JPY | G22: INR | H22: USD
C23: Ober Grandious | D23: 38000000 | E23: =D23*0.3 + D23 -> 49400000 | F23: =E23-D23 -> 11400000 | G23: =F23*J4 -> 19380000 | H23: =F23/J3 -> 121535.18
C24: Phoenix Waseda | D24: 15000000 | E24: =D24*0.3 + D24 -> 19500000 | F24: =E24-D24 -> 4500000 | G24: =F24*J4 -> 7650000 | H24: =F24/J3 -> 47974.414
C25: Urban Hills Waseda | D25: 13500000 | E25: =D25*0.3 + D25 -> 17550000 | F25: =E25-D25 -> 4050000 | G25: =F25*J4 -> 6885000 | H25: =F25/J3 -> 43176.972
C26: Lions Plaza Hakusan | D26: 11000000 | E26: =D26*0.3 + D26 -> 14300000 | F26: =E26-D26 -> 3300000 | G26: =F26*J4 -> 5610000 | H26: =F26/J3 -> 35181.237
C27: Castle mansion | D27: 13500000 | E27: =D27*0.3 + D27 -> 17550000 | F27: =E27-D27 -> 4050000 | G27: =F27*J4 -> 6885000 | H27: =F27/J3 -> 43176.972
C28: Total | D28: =SUM(D23:D27) -> 91000000 | E28: =SUM(E23:E27) -> 118300000 | F28: =SUM(F23:F27) -> 27300000 | G28: =SUM(G23:G27) -> 46410000 | H28: =SUM(H23:H27) -> 291044.78
B31: Capital repayment + Unrealized Profit
C32: Flat | D32: Profit JPY | E32: INR | F32: USD
C33: Ober Grandious | D33: =F23+D15 -> 24181330 | E33: =D33/J4 -> 14224312 | F33: =E33/J3 -> 151645.11
C34: Phoenix Waseda | D34: =F24+D16 -> 7900750 | E34: =D34/J4 -> 4647500 | F34: =E34/J3 -> 49546.908
C35: Urban Hills Waseda | D35: =F25+D17 -> 7002420 | E35: =D35/J4 -> 4119070.6 | F35: =E35/J3 -> 43913.332
C36: Lions Plaza Hakusan | D36: =F26+D18 -> 5440772 | E36: =D36/J4 -> 3200454.1 | F36: =E36/J3 -> 34119.98
C37: Castle mansion | D37: =F27+D19 -> 6344411 | E37: =D37/J4 -> 3732006.5 | F37: =E37/J3 -> 39786.849
C38: Total | D38: =SUM(D33:D37) -> 50869683 | E38: =SUM(E33:E37) -> 29923343 | F38: =SUM(F33:F37) -> 319012.18
B42: Cash
B43: India
C44: Fixed Deposits
D45: Bank | E45: USD | F45: INR | G45: JPY
D46: State Bank of India | E46: 292018 | F46: =E46*J3 -> 27391288 | G46: =E46*J2 -> 46576871
D47: State Bank of India | E47: 5070 | F47: =E47*J3 -> 475566 | G47: =E47*J2 -> 808665
...

Sheet Sheet1
B2: Analysis of Global Assets
B5: ✅ 1. REAL ESTATE — TOTAL
B7: India
B9: Already totaled:
B10: INR 38,500,000
B11: JPY 65,450,000
B12: USD 410,448
B14: Japan (Capital + Unrealized Profit)
B16: Already totaled:
B17: JPY 50,869,683
B18: INR 29,923,343
B19: USD 319,012
B21: 🔹 REAL ESTATE — GRAND TOTAL
B23: Currency | C23: Amount
B24: INR | C24: 68423343
B25: JPY | C25: 116319683
B26: USD | C26: 729460
B29: ✅ 2. CASH — TOTAL
B31: You’ve already given:
B33: India Cash Grand Total
B35: INR 45,286,041
B36: JPY 76,959,287.60
B37: USD 482,504
B39: Japan Cash Grand Total
B41: JPY 7,252,700
B42: INR 4,266,294
B43: USD 45,471
B45: Less: Japan Expenses 2026 + 2027
B47: (1,790,000 + 350,000 = 2,140,000 JPY)
... B62: 🔹 CASH — GRAND TOTAL
B64: Currency | C64: Amount
B65: INR | C65: 48293512
B66: JPY | C66: 82071988
B67: USD | C67: 514558
B70: ✅ 3. PASSIVE INCOME (India Loans + Shriram)
B72: Given:
B73: INR 67,500
B74: JPY 114,750
B75: USD 750
B79: ✅ 4. GOLD + TANAKA + STAMPS + NENKIN
...

Sheet USD to INR Forecast
B2: USD to INR Forecast
B4: https://capex.com/en/overview/usd-to-inr-forecast
B5: https://www.bankbazaar.com/currency-exchange/historical-value-of-1-usd-in-inr.html
B6: Factors that have led to the depreciation of Indian Rupees with respect to the US dollar
B8: Given below are the reasons due to which INR has depreciated with respect to USD:
B10: After India attained its independence in 1947, the Indian Rupee started to be compared to the US dollar. Since there were no credits or debits on the national balance sheet, Re.1 could then be regarded as equal to $1. However, the British pound where £1 was equal to Rs.13 served as the basis for the value of Indian currency, it played a role in the depreciation of the rupee. Furthermore, this pricing of rupee versus the British pound persisted because there was no accepted method of currency comparison until 1944.
B11: The value of the Indian Rupee back in 1947 was 4.76 and stayed consistent till 1966. However, since 1950, the economy of India witnessed a decline, which was due to the country’s credit standing on the global market. Apart from that, the 1962 India-China war, the subsequent India-Pakistan war in 1965, and the 1966 drought all contributed to the situation's deterioration. By 1967, all of them had changed the currency rate from $1 to Rs.7.50.
B12: The value of the rupee also suffered in 1974 as its value fell to 8.10 due to the oil shock in 1973 when OAPEC or the Organisation of Arab Petroleum Exporting Countries decided to reduce proportion. India had to borrow foreign currency to deal with the situation and the ensuing political turmoil. The value of the Indian currency decreased as a result. The exchange rate declined during the course of the 1980s, peaking at 17.50 in the 1990s, down from $1 USD to Rs.7.50 in 1967.
B13: India’s economy suffered back in 1990 as the fiscal deficit decreased by 7.8% of the GDP and India was on the verge of being branded a defaulter in the Indian market. This had a significant impact on the value of the rupee. India had to make their export cheaper and import dearer.
B14: The economic crisis in 1990 played a role in 1992 when the rupee devalued and the exchange rate came to S1 equal to Rs.25.92. Since then, the value of the Indian rupee has started to decline, and it is currently worth Rs.74.57. The dollar price was Rs.45.32 in 2004 and rose to Rs.62.33 over the following ten years. The highest rate of Dollar to rupee ever was recorded in February of 2016, totalling Rs.68.80.
B15: The value of the India rupee also gets affected due to any changes in the Indian rupee. As the value of crude oil in the global markets rises, the value of the Indian rupee drops and vice-versa. Other factors that have led to the value of the rupee depreciating is due to the withdrawal of foreign investors from the Indian markets, increase in government debts which causes the investors to lose interest, subsequently leading to inflation. These factors can cause further drop in the value of Indian rupee.
B17: Factors that Impact Exchange Rates
... B43: How can a countries Exchange rate decrease or become weak
C45: Rising Inflation
C46: Lowing of interest rate
C47: Less Foerign Direct Investment flows
C48: Increase in Trade Deficit or Decrease in Trade Surplus (Imports > Exports)
C49: War or Political Instability
C50: Decrease in Umemployment
C51: Increase in Fuel prices
C52: Increase in Net Outflows out of the country
C53: Decrease in Net Inflows intothe country
C54: Decrease in Rollover rates
B56: https://capex.com/en/overview/usd-to-inr-forecast

Sheet Buy USA Stocks India
B2: https://www.businesstoday.in/markets/market-commentary/story/trading-in-us-stocks-through-nse-ifsc-starts-today-10-things-you-should-know-324575-2022-03-03
B4: Top International Mutual Funds to Invest Online in 2024 through Indian Mutual Fund
C5: https://www.smallcase.com/collections/best-international-mutual-funds/
